<sdf version='1.7'>
  <world name='default'>
    <model name='ground_plane'>
      <static>1</static>
      <link name='link'>
        <collision name='collision'>
          <geometry>
            <plane>
              <normal>0 0 1</normal>
              <size>100 100</size>
            </plane>
          </geometry>
          <surface>
            <friction>
              <ode>
                <mu>100</mu>
                <mu2>50</mu2>
              </ode>
              <torsional>
                <ode/>
              </torsional>
            </friction>
            <contact>
              <ode/>
            </contact>
            <bounce/>
          </surface>
          <max_contacts>10</max_contacts>
        </collision>
        <visual name='visual'>
          <cast_shadows>0</cast_shadows>
          <geometry>
            <plane>
              <normal>0 0 1</normal>
              <size>100 100</size>
            </plane>
          </geometry>
          <material>
            <script>
              <uri>file://media/materials/scripts/gazebo.material</uri>
              <name>Gazebo/Grey</name>
            </script>
          </material>
        </visual>
        <self_collide>0</self_collide>
        <enable_wind>0</enable_wind>
        <kinematic>0</kinematic>
      </link>
    </model>
    <light name='sun' type='directional'>
      <cast_shadows>1</cast_shadows>
      <pose>0 0 10 0 -0 0</pose>
      <diffuse>0.8 0.8 0.8 1</diffuse>
      <specular>0.2 0.2 0.2 1</specular>
      <attenuation>
        <range>1000</range>
        <constant>0.9</constant>
        <linear>0.01</linear>
        <quadratic>0.001</quadratic>
      </attenuation>
      <direction>-0.5 0.1 -0.9</direction>
      <spot>
        <inner_angle>0</inner_angle>
        <outer_angle>0</outer_angle>
        <falloff>0</falloff>
      </spot>
    </light>
    <model name='Dolly'>
      <pose>0 0 0.225 0 -0 0</pose>
      <link name='chassis'>
        <inertial>
          <mass>1</mass>
          <inertia>
            <ixx>0.0227</ixx>
            <ixy>0</ixy>
            <ixz>0</ixz>
            <iyy>0.0852</iyy>
            <iyz>0</iyz>
            <izz>0.1041</izz>
          </inertia>
          <pose>0 0 0 0 -0 0</pose>
        </inertial>
        <visual name='visual'>
          <geometry>
            <box>
              <size>1 0.5 0.15</size>
            </box>
          </geometry>
          <material>
            <script>
              <uri>model://dolly/materials/scripts</uri>
              <uri>model://dolly/materials/textures</uri>
              <name>Dolly/fur</name>
            </script>
          </material>
        </visual>
        <visual name='box'>
          <pose>0 0 0.08 0 -0 0.24</pose>
          <geometry>
            <mesh>
              <uri>model://cardboard_box/meshes/cardboard_box.dae</uri>
              <scale>1.25932 1.00745 0.755591</scale>
            </mesh>
          </geometry>
        </visual>
        <sensor name='sensor_ray' type='ray'>
          <pose>0.5 0 0 0 -0 0</pose>
          <ray>
            <scan>
              <horizontal>
                <samples>200</samples>
                <resolution>1</resolution>
                <min_angle>-1.5707</min_angle>
                <max_angle>1.5707</max_angle>
              </horizontal>
              <vertical>
                <samples>1</samples>
                <min_angle>0</min_angle>
                <max_angle>0</max_angle>
              </vertical>
            </scan>
            <range>
              <min>0.05</min>
              <max>10</max>
            </range>
          </ray>
          <always_on>1</always_on>
          <visualize>1</visualize>
          <update_rate>100</update_rate>
          <plugin name='laser' filename='libgazebo_ros_ray_sensor.so'>
            <ros>
              <namespace>/dolly</namespace>
              <remapping>~/out:=laser_scan</remapping>
            </ros>
            <output_type>sensor_msgs/LaserScan</output_type>
          </plugin>
        </sensor>
        <self_collide>0</self_collide>
        <enable_wind>0</enable_wind>
        <kinematic>0</kinematic>
      </link>
      <link name='caster'>
        <pose>-0.3 0 -0.125 0 -0 0</pose>
        <inertial>
          <mass>0.0415553</mass>
          <inertia>
            <ixx>7.97741e-05</ixx>
            <ixy>0</ixy>
            <ixz>0</ixz>
            <iyy>7.97741e-05</iyy>
            <iyz>0</iyz>
            <izz>7.97741e-05</izz>
          </inertia>
          <pose>0 0 0 0 -0 0</pose>
        </inertial>
        <visual name='visual'>
          <geometry>
            <sphere>
              <radius>0.1</radius>
            </sphere>
          </geometry>
          <material>
            <diffuse>0.5 0.5 0.5 1</diffuse>
            <ambient>0 0 0 1</ambient>
            <specular>1 1 1 1</specular>
            <emissive>0 0 0 1</emissive>
          </material>
        </visual>
        <collision name='collision'>
          <geometry>
            <sphere>
              <radius>0.1</radius>
            </sphere>
          </geometry>
          <surface>
            <friction>
              <ode>
                <mu>1</mu>
                <mu2>1</mu2>
                <slip1>0</slip1>
                <slip2>0</slip2>
              </ode>
              <torsional>
                <ode/>
              </torsional>
            </friction>
            <contact>
              <ode>
                <soft_cfm>0</soft_cfm>
                <soft_erp>0.2</soft_erp>
                <kp>1e+13</kp>
                <kd>1</kd>
                <max_vel>0.01</max_vel>
                <min_depth>0</min_depth>
              </ode>
            </contact>
            <bounce/>
          </surface>
          <max_contacts>10</max_contacts>
        </collision>
        <self_collide>0</self_collide>
        <enable_wind>0</enable_wind>
        <kinematic>0</kinematic>
      </link>
      <link name='left_wheel'>
        <pose>0.3 0.3 -0.075 -1.5707 0 0</pose>
        <inertial>
          <mass>0.5</mass>
          <inertia>
            <ixx>0.0029</ixx>
            <ixy>0</ixy>
            <ixz>0</ixz>
            <iyy>0.0029</iyy>
            <iyz>0</iyz>
            <izz>0.0056</izz>
          </inertia>
          <pose>0 0 0 0 -0 0</pose>
        </inertial>
        <visual name='visual'>
          <geometry>
            <cylinder>
              <radius>0.15</radius>
              <length>0.05</length>
            </cylinder>
          </geometry>
          <material>
            <diffuse>0.5 0.5 0.5 1</diffuse>
            <ambient>0 0 0 1</ambient>
            <specular>1 1 1 1</specular>
            <emissive>0 0 0 1</emissive>
          </material>
        </visual>
        <collision name='collision'>
          <geometry>
            <sphere>
              <radius>0.15</radius>
            </sphere>
          </geometry>
          <surface>
            <friction>
              <ode>
                <mu>1</mu>
                <mu2>1</mu2>
                <slip1>0</slip1>
                <slip2>0</slip2>
              </ode>
              <torsional>
                <ode/>
              </torsional>
            </friction>
            <contact>
              <ode>
                <soft_cfm>0</soft_cfm>
                <soft_erp>0.2</soft_erp>
                <kp>1e+13</kp>
                <kd>1</kd>
                <max_vel>0.01</max_vel>
                <min_depth>0.01</min_depth>
              </ode>
            </contact>
            <bounce/>
          </surface>
          <max_contacts>10</max_contacts>
        </collision>
        <self_collide>0</self_collide>
        <enable_wind>0</enable_wind>
        <kinematic>0</kinematic>
      </link>
      <link name='right_wheel'>
        <pose>0.3 -0.3 -0.075 -1.5707 0 0</pose>
        <inertial>
          <mass>0.5</mass>
          <inertia>
            <ixx>0.0029</ixx>
            <ixy>0</ixy>
            <ixz>0</ixz>
            <iyy>0.0029</iyy>
            <iyz>0</iyz>
            <izz>0.0056</izz>
          </inertia>
          <pose>0 0 0 0 -0 0</pose>
        </inertial>
        <visual name='visual'>
          <geometry>
            <cylinder>
              <radius>0.15</radius>
              <length>0.05</length>
            </cylinder>
          </geometry>
          <material>
            <diffuse>0.5 0.5 0.5 1</diffuse>
            <ambient>0 0 0 1</ambient>
            <specular>1 1 1 1</specular>
            <emissive>0 0 0 1</emissive>
          </material>
        </visual>
        <collision name='collision'>
          <geometry>
            <sphere>
              <radius>0.15</radius>
            </sphere>
          </geometry>
          <surface>
            <friction>
              <ode>
                <mu>1</mu>
                <mu2>1</mu2>
                <slip1>0</slip1>
                <slip2>0</slip2>
              </ode>
              <torsional>
                <ode/>
              </torsional>
            </friction>
            <contact>
              <ode>
                <soft_cfm>0</soft_cfm>
                <soft_erp>0.2</soft_erp>
                <kp>1e+13</kp>
                <kd>1</kd>
                <max_vel>0.01</max_vel>
                <min_depth>0.01</min_depth>
              </ode>
            </contact>
            <bounce/>
          </surface>
          <max_contacts>10</max_contacts>
        </collision>
        <self_collide>0</self_collide>
        <enable_wind>0</enable_wind>
        <kinematic>0</kinematic>
      </link>
      <link name='tail'>
        <pose>-0.52 0 0 -1.6 0 0</pose>
        <inertial>
          <mass>0.0254232</mass>
          <inertia>
            <ixx>1.528e-05</ixx>
            <ixy>0</ixy>
            <ixz>0</ixz>
            <iyy>1.528e-05</iyy>
            <iyz>0</iyz>
            <izz>3.45e-06</izz>
          </inertia>
          <pose>0 0 -0.04 0 -0 0</pose>
        </inertial>
        <visual name='visual'>
          <geometry>
            <cylinder>
              <radius>0.016468</radius>
              <length>0.08</length>
            </cylinder>
          </geometry>
          <material>
            <script>
              <uri>model://dolly/materials/scripts</uri>
              <uri>model://dolly/materials/textures</uri>
              <name>Dolly/fur</name>
            </script>
          </material>
        </visual>
        <self_collide>0</self_collide>
        <enable_wind>0</enable_wind>
        <kinematic>0</kinematic>
      </link>
      <joint name='left_wheel_joint' type='revolute'>
        <parent>chassis</parent>
        <child>left_wheel</child>
        <axis>
          <xyz>0 0 1</xyz>
          <limit>
            <lower>-1.79769e+308</lower>
            <upper>1.79769e+308</upper>
          </limit>
          <dynamics>
            <spring_reference>0</spring_reference>
            <spring_stiffness>0</spring_stiffness>
          </dynamics>
        </axis>
      </joint>
      <joint name='right_wheel_joint' type='revolute'>
        <parent>chassis</parent>
        <child>right_wheel</child>
        <axis>
          <xyz>0 0 1</xyz>
          <limit>
            <lower>-1.79769e+308</lower>
            <upper>1.79769e+308</upper>
          </limit>
          <dynamics>
            <spring_reference>0</spring_reference>
            <spring_stiffness>0</spring_stiffness>
          </dynamics>
        </axis>
      </joint>
      <joint name='caster_wheel' type='ball'>
        <parent>chassis</parent>
        <child>caster</child>
      </joint>
      <joint name='tail_joint' type='revolute'>
        <parent>chassis</parent>
        <child>tail</child>
        <pose>0 0 0.04 0 -0 0</pose>
        <axis>
          <xyz>1 0 0</xyz>
          <limit>
            <lower>-1.79769e+308</lower>
            <upper>1.79769e+308</upper>
            <effort>-1</effort>
            <velocity>-1</velocity>
          </limit>
          <dynamics>
            <spring_reference>0</spring_reference>
            <spring_stiffness>0</spring_stiffness>
            <damping>0</damping>
            <friction>0</friction>
          </dynamics>
        </axis>
        <physics>
          <ode>
            <limit>
              <cfm>0</cfm>
              <erp>0.2</erp>
            </limit>
            <suspension>
              <cfm>0</cfm>
              <erp>0.2</erp>
            </suspension>
          </ode>
        </physics>
      </joint>
      <plugin name='diff_drive' filename='libgazebo_ros_diff_drive.so'>
        <ros>
          <namespace>/dolly</namespace>
        </ros>
        <left_joint>left_wheel_joint</left_joint>
        <right_joint>right_wheel_joint</right_joint>
        <wheel_separation>1.25</wheel_separation>
        <wheel_diameter>0.3</wheel_diameter>
        <max_wheel_torque>20</max_wheel_torque>
        <max_wheel_acceleration>1.0</max_wheel_acceleration>
        <publish_odom>1</publish_odom>
        <publish_odom_tf>1</publish_odom_tf>
        <odometry_frame>odom_demo</odometry_frame>
        <robot_base_frame>chassis</robot_base_frame>
      </plugin>
    </model>
    <gravity>0 0 -9.8</gravity>
    <magnetic_field>6e-06 2.3e-05 -4.2e-05</magnetic_field>
    <atmosphere type='adiabatic'/>
    <physics type='ode'>
      <max_step_size>0.001</max_step_size>
      <real_time_factor>1</real_time_factor>
      <real_time_update_rate>1000</real_time_update_rate>
    </physics>
    <scene>
      <ambient>0.4 0.4 0.4 1</ambient>
      <background>0.7 0.7 0.7 1</background>
      <shadows>1</shadows>
    </scene>
    <wind/>
    <spherical_coordinates>
      <surface_model>EARTH_WGS84</surface_model>
      <latitude_deg>0</latitude_deg>
      <longitude_deg>0</longitude_deg>
      <elevation>0</elevation>
      <heading_deg>0</heading_deg>
    </spherical_coordinates>
    <model name='unit_cylinder'>
      <pose>7.38458 -0.181301 0.5 0 -0 0</pose>
      <link name='link'>
        <inertial>
          <mass>1</mass>
          <inertia>
            <ixx>0.145833</ixx>
            <ixy>0</ixy>
            <ixz>0</ixz>
            <iyy>0.145833</iyy>
            <iyz>0</iyz>
            <izz>0.125</izz>
          </inertia>
          <pose>0 0 0 0 -0 0</pose>
        </inertial>
        <collision name='collision'>
          <geometry>
            <cylinder>
              <radius>0.500001</radius>
              <length>1</length>
            </cylinder>
          </geometry>
          <max_contacts>10</max_contacts>
          <surface>
            <contact>
              <ode/>
            </contact>
            <bounce/>
            <friction>
              <torsional>
                <ode/>
              </torsional>
              <ode/>
            </friction>
          </surface>
        </collision>
        <visual name='visual'>
          <geometry>
            <cylinder>
              <radius>0.500001</radius>
              <length>1</length>
            </cylinder>
          </geometry>
          <material>
            <script>
              <name>Gazebo/Grey</name>
              <uri>file://media/materials/scripts/gazebo.material</uri>
            </script>
          </material>
        </visual>
        <self_collide>0</self_collide>
        <enable_wind>0</enable_wind>
        <kinematic>0</kinematic>
      </link>
    </model>
    <state world_name='default'>
      <sim_time>630 216000000</sim_time>
      <real_time>553 631043158</real_time>
      <wall_time>1670163929 608897072</wall_time>
      <iterations>548536</iterations>
      <model name='Dolly'>
        <pose>-0.021497 -0.000257 0.224726 0.000156 0.000898 0.000831</pose>
        <scale>1 1 1</scale>
        <link name='caster'>
          <pose>-0.321609 -0.000487 0.099996 -1.43456 -0.030786 -0.991272</pose>
          <velocity>-0.000474 2.2e-05 -0.003882 0.001273 0.002764 0</velocity>
          <acceleration>-0.751349 0.149163 -7.76615 0 -0 0</acceleration>
          <wrench>-0.031223 0.006199 -0.322725 0 -0 0</wrench>
        </link>
        <link name='chassis'>
          <pose>-0.021497 -0.000257 0.224726 0.000156 0.000898 0.000831</pose>
          <velocity>-0.001247 1.7e-05 -0.001834 2.9e-05 -0.006057 5e-06</velocity>
          <acceleration>-2.29838 0.085063 -3.66811 0.033068 0.443413 -0.167859</acceleration>
          <wrench>-2.29838 0.085063 -3.66811 0 -0 0</wrench>
        </link>
        <link name='left_wheel'>
          <pose>0.278186 0.300004 0.149503 1.57007 -1.21335 -3.14008</pose>
          <velocity>-0.000878 1.2e-05 0 -8e-05 -0.005856 5e-06</velocity>
          <acceleration>-1.50521 0.022621 0.004154 -0.151249 1.06329 -0.321285</acceleration>
          <wrench>-0.752608 0.01131 0.002077 0 -0 0</wrench>
        </link>
        <link name='right_wheel'>
          <pose>0.278685 -0.299996 0.149409 -1.57054 -0.213203 0.000776</pose>
          <velocity>-0.000855 1.2e-05 1e-06 -8.4e-05 -0.005705 -1.8e-05</velocity>
          <acceleration>-1.56716 0.023543 0.00364 -0.159422 0.853679 -0.409646</acceleration>
          <wrench>-0.783578 0.011772 0.00182 0 -0 0</wrench>
        </link>
        <link name='tail'>
          <pose>-0.541529 0.008853 0.198078 -0.864808 0.000902 0.000833</pose>
          <velocity>-0.000665 -0.095417 0.106334 2.61759 -0.011785 0.001941</velocity>
          <acceleration>-1.12401 0.846502 -9.10216 0.018142 0.041581 -3.01021</acceleration>
          <wrench>-0.028576 0.021521 -0.231406 0 -0 0</wrench>
        </link>
      </model>
      <model name='ground_plane'>
        <pose>0 0 0 0 -0 0</pose>
        <scale>1 1 1</scale>
        <link name='link'>
          <pose>0 0 0 0 -0 0</pose>
          <velocity>0 0 0 0 -0 0</velocity>
          <acceleration>0 0 0 0 -0 0</acceleration>
          <wrench>0 0 0 0 -0 0</wrench>
        </link>
      </model>
      <model name='unit_cylinder'>
        <pose>20 -0.218648 0.499694 0.000109 9.8e-05 0.05103</pose>
        <scale>5.91081 5.91081 1</scale>
        <link name='link'>
          <pose>20 -0.218648 0.499694 0.000109 9.8e-05 0.05103</pose>
          <velocity>0 0 0 0 -0 0</velocity>
          <acceleration>6.5431 -6.54307 -3.25689 -0.238069 -0.021223 0.252356</acceleration>
          <wrench>6.5431 -6.54307 -3.25689 0 -0 0</wrench>
        </link>
      </model>
      <light name='sun'>
        <pose>0 0 10 0 -0 0</pose>
      </light>
    </state>
    <gui fullscreen='0'>
      <camera name='user_camera'>
        <pose>-17.8652 1.29349 21.0847 0 0.779643 0.276195</pose>
        <view_controller>orbit</view_controller>
        <projection_type>perspective</projection_type>
      </camera>
    </gui>
  </world>
</sdf>
